Workbook
Name AverageSpeedLastEight: OFFSET(#REF!,1,0,#REF!,1)
Name AverageSpeedLastEight: OFFSET(#REF!,1,0,#REF!,1)
Name AverageSpeedRealized: OFFSET(#REF!,1,0,#REF!,1)
Name AverageSpeedRealized: OFFSET(#REF!,1,0,#REF!,1)
Name AverageSpeedWorstThree: OFFSET(#REF!,1,0,#REF!,1)
Name ColBottomCurrentScope: OFFSET(#REF!,1,0,#REF!,1)
Name ColTopRemainingWork: OFFSET(#REF!,1,0,#REF!,1)
Name DoneDays: #REF!
Name ImplementationDays: #REF!
Name LastEight: IF(#REF!>8,OFFSET(#REF!,#REF!-7,0,8,1),OFFSET(#REF!,1,0,#REF!-1,1))
Name LastEight: IF(#REF!>8,OFFSET(#REF!,#REF!-7,0,8,1),OFFSET(#REF!,1,0,#REF!-1,1))
Name LastPlanned: IF(OFFSET(#REF!,1,0,1,1)="",1,OFFSET(#REF!,#REF!,0,1,1))
Name LastRealized: IF(OFFSET(#REF!,1,0,1,1)="",1,OFFSET(#REF!,#REF!,0,1,1))
Name PBCurrentBottom: OFFSET(#REF!,1,0,#REF!,1)
Name PBTrend: OFFSET(#REF!,1,0,#REF!,1)
Name PlannedSpeed: OFFSET(#REF!,1,0,#REF!,1)
Name ProductBacklog: 'Backlog del Producto'!$B$13:$P$198
Name RealizedSpeed: OFFSET(#REF!,1,0,#REF!,1)
Name RealizedSpeed: OFFSET(#REF!,1,0,#REF!,1)
Name Sprint: 'Backlog del Producto'!$N$15:$N$198
Name SprintCount: #REF!
Name SprintsInTrend: #REF!
Name SprintTasks: #REF!
Name Status: 'Backlog del Producto'!$O$15:$O$198
Name StoryName: '[1]Backlog del Producto'!#REF!
Name StoryName: 'Backlog del Producto'!#REF!
Name TaskRows: #REF!
Name TaskRows: #REF!
Name TaskStatus: #REF!
Name TaskStoryID: #REF!
Name TotalEffort: #REF!
Name TrendDays: #REF!
Name TrendOffset: #REF!
Name TrendSprintCount: #REF!

Sheet Backlog del Producto
D2: Centro de Teleinformática y Producción Industrial - Regional Cauca
D3: Número de Documento: | E3: FS-DOC- PRODUCT BACKLOG | G3: fecha de Creación | H3: Elaborado por: Grupo de Instructores Area de Software | I3: Pág.1 de2
G5: 45687
D6: Nombre del documento | E6: Historias de Usuario Epicas.
B9: Backlog del Producto | S9: Por Hacer
B10: Nombre del Proyecto: | D10: Sistema de Información Financiera | S10: En Progreso
B11: Dueño del Producto | D11: José Sanchez | S11: Terminado
S12: Eliminado
B13: EPICA | F13: HISTORIA DE USUARIO | J13: OTROS DATOS DE LA EPICA O HISTORIA DE USUARIO
B14: ID Epica | C14: Como (Rol) | D14: Deseo… | E14: Para… | F14: ID Historia de Usuario | G14: Como (Rol)… | H14: Deseo…. | I14: Para…. | J14: Criterios de Aceptación | K14: Prioridad | L14: Estimación | M14: Dependencias | N14: Sprint | O14: Estado | P14: Comentarios
B15: EP-01 Entrenamiento e implementación de OpenIA | C15: Administrador | D15: Entrenar y ajustar un modelo de IA para generar preguntas académicas personalizadas | E15: Para que los estudiantes reciban evaluaciones coherentes, pertinentes y adaptadas a sus necesidades de aprendizaje | F15: ES-395 Entrenamiento y ajuste del modelo de OpenIA | G15: Como administrador del sistema, | H15: quiero iniciar y controlar el proceso de entrenamiento del modelo de inteligencia artificial, definiendo y validando los parámetros académicos como área, nivel, tipo de evaluación, dificultad y estilo de aprendizaje, | I15: para asegurar que el modelo esté correctamente ajustado y preparado para generar preguntas alineadas con los objetivos educativos de la institución. | J15: - El administrador puede iniciar el proceso de entrenamiento del modelo. - El sistema permite definir los parámetros académicos del entrenamiento. - Los insumos del entrenamiento son validados antes de ejecutarse. - El sistema informa el estado del proceso de entrenamiento. - El entrenamiento solo finaliza si los parámetros son válidos. - El sistema confirma cuando el entrenamiento se completa correctamente. - El administrador puede iniciar el proceso de entrenamiento del modelo. - El sistema permite definir los parámetros académicos del entrenamiento. - Los insumos del entrenamiento son validados antes de ejecutarse. - El sistema informa el estado del proceso de entrenamiento. - El entrenamiento solo finaliza si los parámetros son válidos. - El sistema confirma cuando el entrenamiento se completa correctamente. - El administrador puede iniciar el proceso de entrenamiento del modelo. - El sistema permite definir los parámetros académicos del entrenamiento. - Los insumos del entrenamiento son validados antes de ejecutarse. - El sistema informa el estado del proceso de entrenamiento. - El entrenamiento solo finaliza si los parámetros son válidos. - El sistema confirma cuando el entrenamiento se completa correctamente. | N15: 1 | O15: TERMINADO
F16: ES-400 Validación de preguntas generadas por la IA | G16: Como administrador del sistema, | H16: quiero revisar y validar las preguntas académicas generadas por el modelo de inteligencia artificial, | I16: para garantizar que sean coherentes, pertinentes, útiles para los estudiantes y alineadas con los parámetros definidos durante el entrenamiento. | J16: Criterios de Aceptación - El sistema muestra las preguntas generadas por la IA. - Las preguntas incluyen información del área, nivel y dificultad. - El administrador puede revisar el contenido de cada pregunta. - Se puede validar si una pregunta es adecuada o no. - El sistema permite identificar preguntas inconsistentes. - El administrador puede confirmar que el modelo genera resultados aceptables. | M16: ES-395 | N16: 1 | O16: TERMINADO
B17: EP-02 Gestión del Registro Institucional | C17: Administrador | D17: Quiero registrar mi institución en el sistema mediante un formulario completo y validado | E17: Para que pueda acceder a la plataforma y gestionar las evaluaciones académicas de mi institución | F17: ES-295 Registro de institución educativa | G17: Como administrador, | H17: quiero registrar una institución educativa a través de un formulario web que solicite toda la información institucional necesaria, | I17: para crear de manera correcta y segura una cuenta institucional que permita el acceso al sistema y la posterior gestión de estudiantes, docentes y procesos académicos. | J17: -El formulario solicita todos los datos obligatorios de la institución. -No se permite enviar el formulario si falta información requerida. -La contraseña y la confirmación deben coincidir. -El sistema valida el formato del correo institucional. -Se muestran mensajes claros cuando ocurre un error. -Al completar el registro correctamente, el sistema confirma el proceso y redirige al inicio de sesión. | N17: 1 | O17: TERMINADO
B18: EP-03 Gestión de Autenticación Institucional | C18: Administrador | D18: Quiero autenticarme de forma segura en la plataforma mediante mis credenciales institucionales | E18: Para que pueda acceder al sistema y gestionar las funcionalidades correspondientes a mi institución | F18: ES-304 Inicio de sesión institucional | G18: Como administrador institucional, | H18: quiero iniciar sesión en la plataforma utilizando el correo institucional y la contraseña registrados previamente, | I18: para acceder de forma segura al sistema y gestionar la información institucional, académica y administrativa. | J18: - El inicio de sesión solicita correo institucional y contraseña. - Ambos campos son obligatorios. - Si las credenciales son correctas, el sistema permite el acceso. - Si las credenciales son incorrectas, se muestra un mensaje de error. - Si la institución no está registrada, el sistema no permite el ingreso. - El sistema no permite acceder sin autenticación válida. | N18: 1 | O18: TERMINADO
B19: EPIC04 Recuperación de Acceso Institucional | C19: Administrador | D19: Quiero recuperar el acceso a mi cuenta cuando olvide mi contraseña mediante un proceso seguro de verificación | E19: Para que pueda restablecer mis credenciales y volver a acceder a la plataforma sin perder la información de mi institución | F19: ES-313 Solicitud de recuperación de contraseña | G19: Como administrador institucional, | H19: quiero solicitar la recuperación de mi contraseña ingresando el correo institucional registrado en el sistema, | I19: para recibir un código de verificación que me permita confirmar mi identidad y continuar con el proceso de recuperación de acceso. | J19: El sistema solicita el correo institucional. Solo se envía el código si el correo es válido y está registrado. El sistema notifica que el código fue enviado. El código tiene una vigencia de 15 minutos. Si el correo no es válido, se muestra un mensaje de error. | N19: 3 | O19: TERMINADO
F20: ES-328 Validación de código y cambio de contraseña | G20: Como Administrador Institucional | H20: Quiero ingresar el código de verificación recibido y establecer una nueva contraseña segura | I20: Para que pueda completar el proceso de recuperación y acceder nuevamente a mi cuenta con credenciales actualizadas | J20: - El sistema valida que el código sea correcto y esté vigente (15 minutos) - La nueva contraseña debe cumplir requisitos mínimos de seguridad (8 caracteres, mayúscula, número, carácter especial) - Los campos "Contraseña" y "Confirmar contraseña" deben coincidir - Si el código es inválido o expiró, se muestra mensaje de error y opción de reenvío - Al actualizar exitosamente, se muestra confirmación y redirige al login - La contraseña se almacena encriptada y el código usado se invalida | N20: 3 | O20: TERMINADO
B21: EP-05 Inicio Visualización del Desempeño Institucional | C21: Administrador | D21: Que el administrador pueda visualizar de forma centralizada el estado académico de la institución mediante un tablero claro, visual e interactivo. | E21: Para monitorear el progreso mensual y el rendimiento por áreas académicas, facilitando el análisis del avance institucional y la toma de decisiones informadas. | F21: ES-320 Visualización del dashboard institucional | G21: Como administrador institucional, | H21: quiero visualizar un panel principal que muestre de forma organizada la actividad y el desempeño de los estudiantes por cada área académica, utilizando tarjetas, gráficas y barras, | I21: para analizar el rendimiento institucional, comparar el comportamiento de los estudiantes entre meses y tomar decisiones basadas en datos claros y actualizados. | J21: Al iniciar sesión se muestran las tarjetas, la gráfica y las barras del dashboard. El dashboard muestra información separada por áreas académicas. Al pasar el cursor o interactuar con la gráfica, se muestra el detalle del mes seleccionado. Los datos se actualizan cuando un estudiante inicia o cambia de área de práctica. Se presenta la comparación del mes actual frente al mes anterior. El rendimiento por área se visualiza mediante barras. | N21: 1 | O21: TERMINADO
B22: EP-06 Gestión de Estudiantes Institucionales | C22: Administrador | D22: Que el administrador institucional pueda gestionar integralmente a los estudiantes de la institución desde un único módulo del sistema. | E22: Para mantener la información estudiantil organizada, actualizada y trazable, optimizando los procesos de administración académica y facilitando la toma de decisiones institucionales. | F22: ES-338 Visualización y búsqueda de estudiantes | G22: Como administrador institucional, | H22: quiero visualizar el listado de estudiantes de la institución y poder aplicar filtros por grado, curso y jornada, así como realizar búsquedas por nombre y apellido, | I22: para encontrar de manera rápida y organizada la información de los estudiantes y facilitar la gestión académica desde el dashboard institucional.} | J22: Se muestra el listado de estudiantes registrados. Los filtros por grado, curso y jornada funcionan correctamente. La búsqueda por nombre y apellido muestra solo coincidencias. El listado se actualiza según los filtros aplicados. | N22: 2 | O22: TERMINADO
F23: ES-343 Registro de estudiantes y generación de credenciales | G23: Administrador Institucional | H23: quiero registrar estudiantes de forma individual o mediante la importación de archivos CSV o Excel, | I23: para crear sus cuentas de acceso al sistema de manera eficiente y generar automáticamente sus credenciales de usuario y contraseña. | J23: El sistema permite registrar estudiantes de forma individual. Todos los campos obligatorios deben estar diligenciados. Se evita el registro de estudiantes duplicados por documento. Se permite la importación de estudiantes desde archivos CSV o Excel. Al registrar un estudiante correctamente, se generan automáticamente las credenciales. Se muestra un resumen del proceso de importación. | M23: ES-338 | N23: 2 | O23: TERMINADO
F24: ES-349 Administración del estado de estudiantes | G24: Como administrador institucional, | H24: quiero inactivar o eliminar estudiantes según su historial de uso, | I24: para mantener actualizada la información del sistema sin perder la trazabilidad de los registros académicos. | J24: No se permite eliminar estudiantes con historial. Los estudiantes con historial solo pueden ser inactivados. Inactivar o eliminar requiere confirmación. El sistema inactiva automáticamente estudiantes tras 30 días sin ingreso. | M24: ES-343 | N24: 2 | O24: TERMINADO
B25: EP-07 Seguimiento y Análisis del Desempeño Institucional | C25: Administrador Institucional | D25: Visualizar el seguimiento académico del mes en curso mediante dashboards, comparativos, alertas y métricas por áreas académicas. | E25: Para analizar el rendimiento institucional, identificar estudiantes y áreas en riesgo, y generar reportes que apoyen la toma de decisiones académicas oportunas. | F25: ES-356 Visualización de seguimiento académico institucional | G25: Como administrador institucional, | H25: quiero visualizar un resumen del desempeño académico del mes mediante tarjetas y comparativos, | I25: para identificar el progreso de los cursos, áreas críticas y estudiantes que requieren atención. | J25: Muestra tarjetas de resumen del mes. Muestra comparativo por cursos. Identifica estudiantes que requieren atención. Identifica áreas que necesitan refuerzo. | N25: 2 | O25: TERMINADO
F26: ES-362 Detalle de estudiante y generación de reportes PDF | G26: Como administrador institucional, | H26: quiero ver el detalle académico de un estudiante y generar reportes en PDF, | I26: para realizar seguimiento individual y documentar el desempeño académico. | J26: Permite ver el detalle del estudiante. Muestra materias críticas con porcentaje. Permite descargar PDF general e individual. | M26: ES-356 | N26: 3 | O26: TERMINADO
B27: EP-08 Gestión del Dashboard Institucional en Notificaciones | C27: Administrador Institucional | D27: Que el administrador institucional pueda controlar y administrar las notificaciones del sistema, marcándolas, limpiándolas, eliminándolas y filtrándolas según su estado y tipo. | E27: Para mantener el panel de notificaciones organizado, identificar alertas relevantes de manera rápida y facilitar la toma de decisiones oportunas desde el dashboard institucional. | F27: ES-373 Gestión de estado y eliminación de notificaciones | G27: Administrador Institucional | H27: quiero marcar, limpiar o eliminar notificaciones desde el dashboard, | I27: para mantener organizado el panel de notificaciones y asegurar que solo permanezcan visibles las alertas relevantes y pendientes de atención. | J27: El administrador puede marcar todas las notificaciones como leídas. Al marcar todas como leídas, el contador de “No leídas” se actualiza a 0. El administrador puede limpiar todas las notificaciones visibles. El sistema muestra “Sin notificaciones” cuando el listado queda vacío. Se puede eliminar una notificación individual desde su tarjeta. Los contadores se actualizan tras cada acción realizada. | N27: 3 | O27: TERMINADO
F28: ES-368 Visualización de notificaciones institucionales | G28: Administrador Institucional | H28: quiero visualizar las notificaciones generadas por el sistema según el rendimiento académico y la actividad de los estudiantes, organizadas por estado y tipo, | I28: para identificar de forma rápida y clara alertas importantes como bajo rendimiento, inactividad prolongada o áreas que requieren refuerzo, y así tomar decisiones oportunas desde el dashboard institucional. | J28: El sistema muestra un listado de notificaciones. Las notificaciones se pueden filtrar por “Todas” y “No leídas”. El contador de notificaciones coincide con el número real de registros. Cada notificación indica el tipo de alerta y su descripción. Si no existen notificaciones, se muestra el mensaje “Sin notificaciones”. | M28: 373 | N28: 3 | O28: TERMINADO
B29: EP-09 Gestión del perfil institucional | C29: Administrador Institucional | D29: Que el administrador institucional pueda gestionar y actualizar la información general de la institución y las configuraciones asociadas a su cuenta desde su perfil. | E29: Para mantener la información institucional actualizada, asegurar una gestión centralizada y garantizar un acceso seguro y controlado al sistema. | F29: ES-381 Gestión de datos institucionales | G29: Rol: Administrador institucional | H29: quiero visualizar y editar los datos generales de la institución, así como subir o quitar el logo institucional desde mi perfil, | I29: para mantener la información institucional actualizada, identificable y coherente dentro del sistema. | J29: El sistema muestra los datos actuales de la institución al ingresar al perfil. Se permite editar los campos institucionales habilitados. Los campos obligatorios deben validarse antes de guardar. Se puede subir un logo institucional. Se puede quitar o reemplazar el logo existente. Al guardar cambios, el sistema confirma la actualización. La información actualizada se refleja correctamente en el sistema. | N29: 2 | O29: TERMINADO
F30: ES- 389 Cambio de contraseña del administrador | G30: Rol: Administrador institucional | H30: quiero cambiar mi contraseña desde el perfil de usuario, | I30: para mantener la seguridad de mi cuenta y proteger el acceso a la información institucional. | J30: El administrador puede acceder a la opción de cambiar contraseña. Se solicita la contraseña actual para validar el cambio. La nueva contraseña cumple con las reglas de seguridad definidas. El sistema confirma el cambio exitoso de la contraseña.. Si ocurre un error, se muestra un mensaje claro al usuario. | M30: ES-381 | N30: 3 | O30: TERMINADO
B31: EP-10 Pruebas | C31: Equipo de Desarrollo y Aseguramiento de Calidad | D31: Que el equipo de desarrollo y aseguramiento de calidad pueda ejecutar pruebas manuales y automatizadas sobre el aplicativo web y móvil, cubriendo los procesos críticos y los flujos principales del sistema. | E31: Para garantizar que todas las funcionalidades cumplan los requisitos establecidos, asegurar la estabilidad del sistema y reducir riesgos de fallos en producción. | F31: ES-405 Ejecución de pruebas manuales y unitarias | G31: Equipo de Desarrollo y Aseguramiento de Calidad | H31: quiero ejecutar pruebas manuales y pruebas unitarias en el aplicativo web y móvil, | I31: para verificar que todas las funcionalidades estén operativas, cumplan los requisitos establecidos y no presenten fallos funcionales o técnicos. | J31: Se realizan pruebas manuales en todos los módulos del aplicativo. Las pruebas unitarias cubren las funcionalidades principales. Se validan los flujos críticos tanto en web como en móvil. Los errores detectados son documentados. El sistema cumple los requisitos funcionales definidos. No existen fallos críticos sin resolver. | N31: 3 | O31: TERMINADO
F32: ES-411 Automatización de pruebas de autenticación y flujos principales | G32: Equipo de Desarrollo y Aseguramiento de Calidad | H32: quiero implementar pruebas automatizadas sobre el proceso de autenticación y los flujos principales del aplicativo, | I32: para garantizar la estabilidad del sistema, el correcto control de acceso y el funcionamiento continuo de las funcionalidades críticas. | J32: El proceso de autenticación cuenta con pruebas automatizadas. Se validan accesos correctos e incorrectos. Las rutas protegidas son verificadas mediante pruebas automatizadas. Los flujos principales del aplicativo están cubiertos por pruebas automatizadas. Las pruebas pueden ejecutarse de forma repetible. Los resultados de las pruebas son confiables. | N32: 3 | O32: TERMINADO
E35: MOVIL
B36: EP-01 Entrenamiento De OpenIA | C36: Estudiante | D36: Solicitar al sistema preguntas tipo ICFES según un área y subtemas de interés, adaptadas a mi tipo de aprendizaje. | E36: Para practicar de manera personalizada, reforzar los temas que deseo mejorar y evitar la repetición de preguntas durante mi proceso de estudio. | F36: ES-256 Entrenamiento de OpenIA por área y subtemas | G36: Como estudiante, | H36: quiero seleccionar un área académica y uno o varios subtemas de mi interés para solicitar al sistema un entrenamiento personalizado | I36: para practicar con preguntas tipo ICFES adaptadas a mi estilo de aprendizaje y reforzar específicamente los temas en los que deseo mejorar mi desempeño. | J36: El estudiante puede seleccionar un área y subtemas específicos. El sistema genera preguntas tipo ICFES relacionadas con los subtemas seleccionados. Las preguntas no se repiten dentro del mismo entrenamiento. Las preguntas se adaptan al estilo de aprendizaje del estudiante. | N36: 1 | O36: TERMINADO
B37: EP-03 Autenticación de Estudiantes (Móvil) | C37: Estudiante | D37: Iniciar sesión en el aplicativo móvil EduExce utilizando las credenciales proporcionadas por la institución. | E37: Para acceder de manera segura a las funcionalidades del sistema y utilizar la plataforma según mi perfil de estudiante. | F37: EP-101 Inicio de sesión del estudiante | G37: Como estudiante, | H37: quiero iniciar sesión en el aplicativo móvil utilizando el usuario y contraseña entregados por mi institución, | I37: para acceder a las funcionalidades educativas de EduExce y realizar mis actividades académicas dentro de la aplicación. | J37: El inicio de sesión solicita usuario y contraseña. Ambos campos son obligatorios. Si el estudiante no está registrado, no se permite el ingreso. Si las credenciales son correctas, se permite el acceso. Si las credenciales son incorrectas, se muestra un mensaje de error. | N37: 1 | O37: TERMINADO
B38: EP-03 EP-03 Recuperación de acceso del estudiante | C38: Estudiante | D38: Recuperar el acceso a la aplicación móvil EduExce restableciendo mi contraseña mediante un código de verificación enviado a mi correo electrónico. | E38: Para volver a ingresar de forma segura a la aplicación cuando olvido mis credenciales y continuar usando el sistema sin interrupciones. | F38: EP-108 Solicitud de recuperación de contraseña | G38: Como estudiante, | H38: quiero solicitar la recuperación de mi contraseña ingresando el correo electrónico que tengo registrado en la aplicación, | I38: para recibir un código de verificación que me permita confirmar mi identidad y continuar con el proceso de restablecimiento de acceso a la app. | J38: El sistema solicita el correo electrónico del estudiante. El correo debe estar registrado en el sistema. El sistema genera un código de verificación de 6 dígitos. El código tiene una vigencia de 15 minutos. Se muestra un mensaje indicando que el código fue enviado. Si el correo no existe, se muestra un mensaje de error. | N38: 1 | O38: TERMINADO
F39: EP- 116 Validación de código y cambio de contraseña | G39: Como estudiante, | H39: quiero ingresar el código de verificación recibido y definir una nueva contraseña, | I39: para recuperar el acceso a la aplicación móvil de forma segura y continuar utilizando todas sus funcionalidades. | J39: El sistema solicita el código de verificación. El código debe tener exactamente 6 dígitos. El sistema valida coincidencia y vigencia del código. Con código válido y vigente se habilita el cambio de contraseña. La nueva contraseña debe tener exactamente 13 caracteres. La confirmación debe coincidir con la nueva contraseña. Al finalizar, el sistema confirma el cambio y redirige al inicio de sesión. | M39: EP-108 | N39: 4 | O39: TERMINADO
B40: EP-04 Evaluación del Estilo de Aprendizaje del Estudiante | C40: Estudiante | D40: Recuperar el acceso a la aplicación móvil EduExce restableciendo mi contraseña mediante un código de verificación enviado a mi correo electrónico. | E40: Para volver a ingresar de forma segura a la aplicación cuando olvido mis credenciales y continuar usando el sistema sin interrupciones. | F40: EP-127 Realización del Test de Kolb en el primer ingreso | G40: Como estudiante, | H40: quiero realizar el Test de David Kolb al ingresar por primera vez a la aplicación móvil, respondiendo todas las preguntas de manera obligatoria, | I40: para que el sistema identifique mi estilo de aprendizaje y pueda ofrecerme una experiencia educativa personalizada acorde a mi forma de aprender. | J40: El test se presenta automáticamente en el primer ingreso del estudiante. El test solo se muestra una vez si ya fue realizado. El test contiene 36 preguntas organizadas en 4 bloques de 9 preguntas. Cada pregunta tiene una escala de respuesta de 1 a 4. No se permite avanzar sin responder la pregunta actual. No se permite finalizar el test si existen preguntas sin responder. Al finalizar el test, el sistema determina el estilo de aprendizaje del estudiante: Divergente Asimilador Acomodador Convergente Una vez finalizado el test, el estudiante puede continuar usando la aplicación. | N40: 1 | O40: TERMINADO
B41: EP-05 Diagnóstico Inicial del Estudiante | C41: Estudiante | D41: Presentar y desarrollar el diagnóstico académico inicial dentro de la aplicación móvil y visualizar mis resultados por área y porcentaje global. | E41: Para conocer mi nivel de conocimiento al ingresar al sistema y habilitar el acceso completo a las funcionalidades del aplicativo móvil. | F41: EP-137 Presentación y desarrollo del diagnóstico inicial | G41: Como estudiante, | H41: quiero que al interactuar por primera vez con la aplicación se me presente un diagnóstico académico inicial con preguntas obligatorias, | I41: para evaluar mis conocimientos en las diferentes áreas antes de utilizar las funcionalidades del aplicativo | J41: El diagnóstico se presenta solo la primera vez que el estudiante interactúa con la app. No se permite finalizar el diagnóstico si existen preguntas sin responder. Todas las preguntas deben ser respondidas obligatoriamente. El diagnóstico está compuesto por 5 bloques con 5 preguntas cada uno (25 preguntas en total). Las preguntas del diagnóstico son dinámicas. Si el diagnóstico no está completo, cualquier intento de interacción vuelve a mostrar el cuestionario. | N41: 1 | O41: TERMINADO
F42: EP-143 Visualización de resultados y habilitación del acceso | G42: Como estudiante, | H42: quiero visualizar los resultados del diagnóstico inicial organizados por área y un porcentaje global, | I42: para conocer mi nivel académico inicial y poder acceder a todas las funcionalidades del aplicativo. | J42: Al finalizar el diagnóstico, se muestran los resultados por área. Se muestra el porcentaje global de desempeño. Las áreas evaluadas son: Lectura Crítica, Matemáticas, Sociales y Ciudadanas, Ciencias Naturales e Inglés. Una vez mostrados los resultados, se habilita el acceso completo a la aplicación. El diagnóstico no vuelve a mostrarse si ya fue completado. | M42: EP-137 | N42: 1 | O42: TERMINADO
B43: EP-06 Navegación y Progresión Académica en el Mapa de Islas | C43: Estudiante | D43: Navegar por un mapa interactivo de islas para acceder a las áreas académicas, realizar la Prueba de Conocimiento y avanzar progresivamente por niveles según mi desempeño. | E43: Para vivir una experiencia de aprendizaje guiada y motivadora, reforzar mis conocimientos por áreas y visualizar mis resultados académicos de forma clara al finalizar cada actividad. | F43: EP-149 Progreso por áreas académicas en el mapa de islas | G43: Como estudiante, | H43: quiero ingresar a las islas correspondientes a las áreas académicas y avanzar por niveles de forma progresiva según mis resultados, | I43: para fortalecer mis conocimientos por área, visualizar mi progreso y desbloquear nuevos retos a medida que demuestro un mejor desempeño académico. | J43: El mapa muestra 5 islas correspondientes a las áreas académicas. Cada área contiene 5 niveles y un examen final. Al iniciar, solo el primer nivel de cada área está desbloqueado. Se avanza al siguiente nivel al obtener mínimo 4 aciertos. Desde el nivel 2, el estudiante dispone de 3 vidas. Si se agotan las vidas, el estudiante regresa al nivel anterior. Al completar los 5 niveles se habilita el examen final del área. Al finalizar cualquier actividad, se muestran resultados por área y porcentaje global. | N43: 2 | O43: TERMINADO
F44: EP-157 Prueba de Conocimiento en modalidad fácil y difícil | G44: Como estudiante, | H44: quiero realizar la Prueba de Conocimiento eligiendo entre una modalidad fácil o difícil, | I44: para evaluar mi nivel académico general bajo diferentes condiciones de tiempo y dificultad, y conocer mis resultados globales de desempeño. | J44: La isla de Prueba de Conocimiento está disponible desde el inicio. El estudiante puede elegir entre modalidad fácil y difícil. Ambas modalidades contienen 25 preguntas dinámicas. En modalidad fácil no hay límite de tiempo por pregunta. En modalidad difícil cada pregunta tiene un límite de 1 minuto. Si se acaba el tiempo en modalidad difícil, la pregunta queda sin responder. Al finalizar, solo se muestran resultados por área y porcentaje global. | N44: 2 | O44: TERMINADO
A45: EP-164 | B45: EP-07 Generación de Preguntas Académicas | C45: Estudiante | D45: Responder preguntas académicas generadas dinámicamente por inteligencia artificial, adaptadas a mi nivel, subtema y estilo de aprendizaje, con retroalimentación inmediata. | E45: Para evaluar mi desempeño, recibir recomendaciones personalizadas que fortalezcan mi aprendizaje y permitir que el sistema registre mi historial académico para un seguimiento continuo. | F45: EP-164 Resolución de preguntas dinámicas generadas por IA | G45: Como estudiante, | H45: quiero que al ingresar a un nivel el sistema genere automáticamente preguntas dinámicas mediante inteligencia artificial, alineadas al subtema del nivel y adaptadas a mi estilo de aprendizaje, | I45: para practicar los contenidos académicos de forma personalizada, diferente en cada intento y acorde a mi manera de aprender. | J45: Cada nivel genera exactamente 5 preguntas dinámicas. Las preguntas están alineadas al subtema del nivel. Las preguntas se adaptan al estilo de aprendizaje del estudiante según el Test de Kolb. Las preguntas se reemplazan cada vez que el estudiante vuelve a practicar el nivel. En la Isla de Conocimiento y el examen final, las preguntas provienen del banco de preguntas. | N45: 1 | O45: TERMINADO
F46: EP-170 Evaluación inmediata y recomendaciones | G46: Como estudiante, | H46: quiero recibir retroalimentación inmediata sobre cada respuesta que selecciono y obtener recomendaciones personalizadas según mi desempeño, | I46: para identificar mis errores, reforzar los subtemas donde tengo dificultades y mejorar progresivamente mis resultados académicos. | J46: El sistema indica si la respuesta es correcta o incorrecta. Se muestra la opción marcada por el estudiante junto con la opción correcta. La IA analiza las respuestas del estudiante. Se generan recomendaciones personalizadas por subtema. Las recomendaciones se reemplazan cuando el estudiante vuelve a practicar. Los resultados se almacenan en el historial académico del estudiante. | N46: 2 | O46: TERMINADO
...

Sheet tareas por historias 
A2: Id Tarea | B2: ID Historia | C2: Tarea | D2: Tipo de Tarea (RF/RNF) | E2: Estimación (días) | F2: Responsable | G2: Dependencias (ID) | H2: Prioridad | I2: Estado (%) | J2: Condición de aprobación | K2: Aprobado | L2: Miembro del equipo que lo especifico.
A3: 1 | B3: HU01 | C3: Pagina Principal | D3: RF/RNF | E3: 5 Dias | F3: Pedro | G3: Esta relacionada con 3. Registro 12.Iniciar secion | H3: ALTA | I3: 0 | J3: Mostrar el Login, seccion de noticias, Tutorial y ajuste de pantalla de acuerdo a la resolucion de pantalla (Responsive Web Design). | L3: Hamilton
A4: ES-396 | B4: ES-395 - Entrenamiento y ajuste del modelo de OpenIA | C4: Diseñar la interfaz de configuración del entrenamiento | D4: RF | E4: 4 dias | F4: Carlos Pinza | G4: Ninguna | H4: ALTA | I4: 1 | J4: Crear la pantalla donde el administrador define parámetros como área, nivel, tipo de evaluación, dificultad y estilo de aprendizaje. | K4: Si | L4: Carlos Pinza
A5: ES-397 | B5: ES-395 - Entrenamiento y ajuste del modelo de OpenIA | C5: Validar los insumos del entrenamiento | D5: RF | E5: 4 dias | F5: Carlos Pinza | G5: ES-395 | H5: ALTA | I5: 1 | J5: Implementar validaciones para asegurar que los parámetros definidos sean completos y coherentes antes de iniciar el entrenamiento. | K5: Si | L5: Carlos Pinza
A6: ES-398 | B6: ES-395 - Entrenamiento y ajuste del modelo de OpenIA | C6: Implementar la lógica para iniciar el entrenamiento del modelo | D6: RF | E6: 4 dias | F6: Carlos Pinza | G6: ES-395 | H6: ALTA | I6: 1 | J6: Desarrollar la funcionalidad que permita ejecutar el proceso de entrenamiento del modelo de IA. | K6: Si | L6: Carlos Pinza
A7: ES-399 | B7: ES-395 - Entrenamiento y ajuste del modelo de OpenIA | C7: Monitorear el estado del proceso de entrenamiento | D7: RF | E7: 4 dias | F7: Carlos Pinza | G7: ES-395 | H7: Alta | I7: 1 | J7: Mostrar al administrador el progreso, estado y finalización del entrenamiento. | K7: Si | L7: Carlos Pinza
A8: ES-401 | B8: ES-400 - Validación de preguntas generadas por la IA | C8: Mostrar las preguntas generadas por la IA | D8: RF | E8: 4 dias | F8: Carlos Pinza | G8: Ninguna | H8: Alta | I8: 1 | J8: Implementar la visualización de las preguntas producidas por el modelo entrenado. | K8: Si | L8: Carlos Pinza
A9: ES-402 | B9: ES-400 - Validación de preguntas generadas por la IA | C9: Asociar metadatos académicos a cada pregunta | D9: RF | E9: 4 dias | F9: Carlos Pinza | G9: ES-401 | H9: Alta | I9: 1 | J9: Mostrar información como área, nivel, tipo de evaluación y dificultad. | K9: Si | L9: Carlos Pinza
A10: ES-403 | B10: ES-400 - Validación de preguntas generadas por la IA | C10: Permitir revisión individual de preguntas | D10: RF | E10: 4 dias | F10: Carlos Pinza | G10: ES-402 | H10: Alta | I10: 1 | J10: Facilitar la lectura y análisis detallado de cada pregunta generada. | K10: Si | L10: Carlos Pinza
A11: ES-404 | B11: ES-400 - Validación de preguntas generadas por la IA | C11: Implementar validación de calidad de preguntas | D11: RF | E11: 4 dias | F11: Carlos Pinza | G11: ES-403 | H11: Alta | I11: 1 | J11: Permitir marcar preguntas como válidas o no válidas según criterios académicos. | K11: Si | L11: Carlos Pinza
A12: ES-420 | B12: EP-02 Registro de inhstitucion | C12: Diseñar formulario de registro institucional | D12: RF | E12: 4 dias | F12: Sirley | G12: Ningu | H12: Alta | I12: 100%% | J12: El formulario incluye todos los campos requeridos y se visualiza correctamente | K12: si | L12: Sirkley Diaz
A13: ES-421 | B13: HU-01 Registro de inhstitucion | C13: Implementar validación de campos obligatorios | D13: RF | E13: 4 Dias | F13: Sirley | G13: ES-420 | H13: alta | J13: El sistema no permite enviar el formulario con campos obligatorios vacíos | K13: Si | L13: Sirkley Diaz
A14: ES-422 | B14: HU-01 Registro de inhstitucion | C14: Validar coincidencia de contraseña | D14: RF | E14: 4dias | F14: Sirley | G14: ES-421 | H14: alta | I14: 10 | J14: La contraseña y la confirmación coinciden antes de permitir el registro | K14: si | L14: Sirley Diaz
A15: ES-423 | B15: HU-01 Registro de inhstitucion | C15: Validar formato de correo institucional | D15: RF | E15: 4 Dias | F15: Sirley | G15: ES-422 | H15: Alta | I15: 1 | J15: El sistema valida que el correo tenga un formato correcto | K15: SI | L15: Sirley Diaz
A16: ES-424 | B16: HU-01 Registro de inhstitucion | C16: Mostrar mensajes de error por validación | D16: RF | E16: 4dias | F16: Sirley | G16: E-420,421,422 | H16: Alta | I16: 1 | J16: Se muestran mensajes claros indicando el error y cómo corregirlo | K16: SI | L16: Sirley Diaz
A17: ES-426 | B17: HU-01 Registro de inhstitucion | C17: Registrar institución en la base de datos | D17: RF | E17: 4dias | F17: Sirley | G17: ES-424 | H17: Alta | I17: 1 | J17: La información de la institución se guarda correctamente en la base de datos | K17: Si | L17: Sirley Diaz
A18: ES-427 | B18: HU-01 Registro de inhstitucion | C18: Mostrar mensaje de registro exitoso | D18: RF | E18: 4dias | F18: Sirley | G18: ES-.425 | H18: Alta | I18: 1 | J18: El sistema muestra confirmación visual de registro exitoso | K18: Si | L18: Sirley Diaz
A19: 428 | B19: HU-01 Registro de inhstitucion | C19: Redirigir al inicio de sesión | D19: RF | E19: 4dias | F19: Sirley | G19: ES-426 | H19: Alta | I19: 1 | J19: El usuario es redirigido al login después del registro exitoso | K19: Si | L19: Sirley Diaz
A20: T-01 | B20: HU-01 Inicio de sesión institucional | C20: Crear formulario de inicio de sesión institucional | D20: RF | E20: 4 dias | F20: Sirley | G20: Ningu | H20: Alta | I20: 1 | J20: La interfaz muestra los campos de correo institucional y contraseña correctamente | K20: Si | L20: Sirley Diaz
A21: T-.02 | B21: HU-01 Inicio de sesión institucional | C21: Validar campos obligatorios de inicio de sesión | D21: RF | E21: 4 dias | F21: Sirley | G21: T-01 | H21: Alta | I21: 1 | J21: El sistema impide el envío si el correo o la contraseña están vacíos | K21: Si | L21: Sirley Diaz
A22: T-03 | B22: HU-01 Inicio de sesión institucional | C22: Validar existencia de la institución | D22: RF | E22: 4 dias | F22: Sirley | G22: T-02 | H22: Alta | I22: 1 | J22: El sistema verifica que el correo institucional esté asociado a una institución registrada | K22: Si | L22: Sirley Diaz
A23: T-04 | B23: HU-01 Inicio de sesión institucional | C23: Validar credenciales de acceso | D23: RF | E23: 4 dias | F23: Sirley | G23: T-03 | H23: Alta | I23: 1 | J23: El sistema compara correctamente el correo y la contraseña con los datos almacenados | K23: Si | L23: Sirley Diaz
A24: T-05 | B24: HU-01 Inicio de sesión institucional | C24: Permitir acceso al sistema | D24: RF | E24: 4 dias | F24: Sirley | G24: T-04 | H24: Alta | I24: 1 | J24: El administrador accede al sistema cuando las credenciales son correctas | K24: Si | L24: Sirley Diaz
A25: T-06 | B25: HU-01 Inicio de sesión institucional | C25: Mostrar mensaje de error por credenciales incorrectas | D25: RF | E25: 4 dias | F25: Sirley | G25: T-04 | H25: Alta | I25: 1 | J25: El sistema informa claramente cuando el correo o la contraseña no son válidos | K25: Si | L25: Sirley Diaz
A26: T-07 | B26: HU-01 Inicio de sesión institucional | C26: Bloquear acceso cuando la institución no existe | D26: RF | E26: 4 dias | F26: Sirley | G26: T-03 | H26: Alta | I26: 1 | J26: Se bloquea el acceso y se muestra un mensaje si la institución no está registrada | K26: Si | L26: Sirley Diaz
A27: T-08 | B27: HU-01 Inicio de sesión institucional | C27: Redirigir al panel institucional | D27: RF | E27: 4 dias | F27: Sirley | G27: T-05 | H27: Alta | I27: 1 | J27: El administrador es redirigido al panel institucional tras iniciar sesión correctamente | K27: Si | L27: Sirley Diaz
A28: T-01 | B28: HU-01 Solicitud de recuperación de contraseña | C28: Crear formulario de recuperación de acceso | D28: RF | E28: 4 dias | F28: Bryan | G28: Ningu | H28: Alta | I28: 1 | J28: La interfaz permite ingresar el correo institucional correctamente | K28: Si | L28: Bryan
A29: T-02 | B29: HU-01 Solicitud de recuperación de contraseña | C29: Validar formato y existencia del correo institucional | D29: RF | E29: 4 dias | F29: Bryan | G29: T-01 | H29: Alta | I29: 1 | J29: El sistema valida formato y existencia del correo en la base de datos | K29: Si | L29: Bryan
A30: T-03 | B30: HU-01 Solicitud de recuperación de contraseña | C30: Generar código de verificación de 6 dígitos | D30: RF | E30: 4 dias | F30: Bryan | G30: T-02 | H30: Alta | I30: 1 | J30: Se genera un código único de 6 dígitos para recuperación | K30: Si | L30: Bryan
A31: T-04 | B31: HU-01 Solicitud de recuperación de contraseña | C31: Enviar código de verificación al correo | D31: RF | E31: 4 dias | F31: Bryan | G31: T-03 | H31: Alta | I31: 1 | J31: El código es enviado correctamente al correo institucional | K31: Si | L31: Bryan
... A106: ES-.418 | B106: ES-411 Automatización de pruebas de autenticación y flujos principales | C106: Automatizar perfil de usuario | D106: RF | E106: 4 dias | F106: Ana | G106: Probar todo el aplicativo, prueba de todas las tareas (TODAS) | H106: Alta | I106: 1 | J106: Validar el correcto funcionamiento del perfil del usuario mediante pruebas automatizadas. | K106: si | L106: Ana
G107: MOVIL
A108: EP-257 | B108: HU-256 Entrenamiento de OpneIA por área y subtemas | C108: Crear interfaz de selección de área y subtemas | D108: RF | E108: 4 DIAS | F108: Pinza | H108: alta | I108: 1 | J108: Diseñar la pantalla donde el estudiante pueda elegir el área académica y los subtemas específicos que desea practicar. | K108: si | L108: Pinza
A109: EP-258 | B109: HU-256 Entrenamiento de OpneIA por área y subtemas | C109: Validar selección de área y subtemas | D109: RF | E109: 4 DIAS | F109: Pinza | G109: EP-257 | H109: alta | I109: 1 | J109: Verificar que el estudiante haya seleccionado al menos un área y un subtema antes de realizar la petición al sistema. | K109: si | L109: Pinza
A110: EP-259 | B110: HU-256 Entrenamiento de OpneIA por área y subtemas | C110: Enviar petición de entrenamiento al sistema | D110: RF | E110: 4 DIAS | F110: Pinza | G110: EP-258 | H110: alta | I110: 1 | J110: Implementar la lógica para enviar al backend el área, los subtemas seleccionados y el estilo de aprendizaje del estudiante. | K110: si | L110: Pinza
A111: EP-260 | B111: HU-256 Entrenamiento de OpneIA por área y subtemas | C111: Generar preguntas tipo ICFES con IA | D111: RF | E111: 4 DIAS | F111: Pinza | G111: EP-259 | H111: alta | I111: 1 | J111: Procesar la solicitud utilizando inteligencia artificial para generar preguntas alineadas con los subtemas y el estilo de aprendizaje del estudiante. | K111: si | L111: Pinza
A112: EP-261 | B112: HU-256 Entrenamiento de OpneIA por área y subtemas | C112: Mostrar preguntas adaptadas al estudiante | D112: RF | E112: 4 DIAS | F112: Pinza | G112: EP-260 | H112: alta | I112: 1 | J112: Presentar las preguntas generadas de forma clara y ordenada para que el estudiante pueda iniciar la práctica | K112: si | L112: Pinza
A113: EP-262 | B113: HU-256 Entrenamiento de OpneIA por área y subtemas | C113: Registrar interacción del estudiante | D113: RF | E113: 4 DIAS | F113: sirley dias | G113: EP-261 | H113: alta | I113: 1 | J113: Guardar en el sistema la información del entrenamiento realizado para fines de seguimiento y mejora del aprendizaje. | K113: si | L113: sirley dias
A114: EP-102 | B114: HU-101 Inicio de sesión del estudiante | C114: Crear interfaz de inicio de sesión para estudiantes | D114: RF | E114: 4 DIAS | F114: Sirley | G114: n | H114: alta | I114: 1 | J114: Diseñar la pantalla móvil que permita al estudiante ingresar usuario y contraseña. | K114: si | L114: sirley dias
A115: EP-103 | B115: HU-101 Inicio de sesión del estudiante | C115: Validar campos obligatorios de inicio de sesión | D115: RF | E115: 4 DIAS | F115: Sirley | G115: EP-102 | H115: alta | I115: 1 | J115: Verificar que ambos campos estén diligenciados antes de permitir el envío de la información. | K115: si | L115: sirley dias
...

Sheet Sprints
B2: Sprint | C2: Inicio | D2: Días | E2: Final | F2: Estimación | G2: Estado | H2: Fecha Liberación | I2: Meta
B3: 1 web | C3: 45831 | D3: 37 | E3: 42217 | F3: 100 | G3: Planeado | H3: 45871 | I3: Se cumplio con la meta de este Sprint
B4: 2 web | C4: 45873 | D4: 31 | E4: 45905 | F4: 100 | G4: Planeado | H4: 45904 | I4: Se cumplio con la meta de este Sprint
B5: 3 wed | C5: 45908 | D5: 18 | E5: 45926 | F5: 100 | G5: Planeado | H5: 45927 | I5: Se cumplio con la meta de este Sprint
B6: 1 movil | C6: 45887 | D6: 30 | E6: 45926 | F6: 100 | G6: Planeado | H6: 45928 | I6: Se cumplio con la meta de este Sprint
B7: 2 movil | C7: 45929 | D7: 20 | E7: 45947 | F7: 100 | G7: Planeado | H7: 45948 | I7: Se cumplio con la meta de este Sprint
B8: 3 movil | C8: 45950 | D8: 20 | E8: 45968 | F8: 100 | G8: Planeado | H8: 45969 | I8: Se cumplio con la meta de este Sprint
B9: 4 movil | C9: 45971 | D9: 25 | E9: 45995 | F9: 100 | G9: Planeado | H9: 45996 | I9: Se cumplio con la meta de este Sprint
B10: =IF(AND(C10<>"",D10<>""),B9+1,"") | C10: =IF(AND(C9<>"",D9<>"",D10<>""),C9+D9,"") | E10: =IF(AND(C10<>"",D10<>""),C10+D10-1,"") | F10: =IF(B10="","",SUMIF('Backlog del Producto'!N$16:N$138,Sprints!B10,'Backlog del Producto'!L$16:L$138)) | G10: =IF(AND(OR(G9="Planned",G9="Ongoing"),D10<>""),"Planned","Unplanned") -> Unplanned
B11: =IF(AND(C11<>"",D11<>""),B10+1,"") | C11: =IF(AND(C10<>"",D10<>"",D11<>""),C10+D10,"") | E11: =IF(AND(C11<>"",D11<>""),C11+D11-1,"") | F11: =IF(B11="","",SUMIF('Backlog del Producto'!N$16:N$138,Sprints!B11,'Backlog del Producto'!L$16:L$138)) | G11: =IF(AND(OR(G10="Planned",G10="Ongoing"),D11<>""),"Planned","Unplanned") -> Unplanned
B12: =IF(AND(C12<>"",D12<>""),B11+1,"") | C12: =IF(AND(C11<>"",D11<>"",D12<>""),C11+D11,"") | E12: =IF(AND(C12<>"",D12<>""),C12+D12-1,"") | F12: =IF(B12="","",SUMIF('Backlog del Producto'!N$16:N$138,Sprints!B12,'Backlog del Producto'!L$16:L$138)) | G12: =IF(AND(OR(G11="Planned",G11="Ongoing"),D12<>""),"Planned","Unplanned") -> Unplanned
B13: =IF(AND(C13<>"",D13<>""),B12+1,"") | C13: =IF(AND(C12<>"",D12<>"",D13<>""),C12+D12,"") | E13: =IF(AND(C13<>"",D13<>""),C13+D13-1,"") | F13: =IF(B13="","",SUMIF('Backlog del Producto'!N$16:N$138,Sprints!B13,'Backlog del Producto'!L$16:L$138)) | G13: =IF(AND(OR(G12="Planned",G12="Ongoing"),D13<>""),"Planned","Unplanned") -> Unplanned
B14: =IF(AND(C14<>"",D14<>""),B13+1,"") | C14: =IF(AND(C13<>"",D13<>"",D14<>""),C13+D13,"") | E14: =IF(AND(C14<>"",D14<>""),C14+D14-1,"") | F14: =IF(B14="","",SUMIF('Backlog del Producto'!N$16:N$138,Sprints!B14,'Backlog del Producto'!L$16:L$138)) | G14: =IF(AND(OR(G13="Planned",G13="Ongoing"),D14<>""),"Planned","Unplanned") -> Unplanned
B15: =IF(AND(C15<>"",D15<>""),B14+1,"") | C15: =IF(AND(C14<>"",D14<>"",D15<>""),C14+D14,"") | E15: =IF(AND(C15<>"",D15<>""),C15+D15-1,"") | F15: =IF(B15="","",SUMIF('Backlog del Producto'!N$16:N$138,Sprints!B15,'Backlog del Producto'!L$16:L$138)) | G15: =IF(AND(OR(G14="Planned",G14="Ongoing"),D15<>""),"Planned","Unplanned") -> Unplanned
B16: =IF(AND(C16<>"",D16<>""),B15+1,"") | C16: =IF(AND(C15<>"",D15<>"",D16<>""),C15+D15,"") | E16: =IF(AND(C16<>"",D16<>""),C16+D16-1,"") | F16: =IF(B16="","",SUMIF('Backlog del Producto'!N$16:N$138,Sprints!B16,'Backlog del Producto'!L$16:L$138)) | G16: =IF(AND(OR(G15="Planned",G15="Ongoing"),D16<>""),"Planned","Unplanned") -> Unplanned
B17: =IF(AND(C17<>"",D17<>""),B16+1,"") | C17: =IF(AND(C16<>"",D16<>"",D17<>""),C16+D16,"") | E17: =IF(AND(C17<>"",D17<>""),C17+D17-1,"") | F17: =IF(B17="","",SUMIF('Backlog del Producto'!N$16:N$138,Sprints!B17,'Backlog del Producto'!L$16:L$138)) | G17: =IF(AND(OR(G16="Planned",G16="Ongoing"),D17<>""),"Planned","Unplanned") -> Unplanned
E18: Historias sin Asignar | F18: =SUMIF('Backlog del Producto'!N$16:N$138,"",'Backlog del Producto'!L$16:L$138)-SUMIF('Backlog del Producto'!O$16:O$138,"Eliminado",'Backlog del Producto'!L$16:L$138) -> 0
